<?xml version="1.0" encoding="utf-8"?>
<robot name="X5liteaa0">
    <link name="base_link">
        <inertial>
            <origin xyz="-0.00013359 6.672E-05 0.031672" rpy="0 0 0"/>
            <mass value="0.42272"/>
            <inertia ixx="0.00019" ixy="0.00000" ixz="0.00000" iyy="0.00019" iyz="0.00000" izz="0.00020"/>
        </inertial>
        <visual>
            <origin xyz="0 0 0" rpy="0 0 0"/>
            <geometry>
                <box size="0.1 0.1 0.1"/>
            </geometry>
            <material name="base_material">
                <color rgba="0.89804 0.91765 0.92941 1"/>
            </material>
        </visual>
        <collision>
            <origin xyz="0 0 0" rpy="0 0 0"/>
            <geometry>
                <box size="0.1 0.1 0.1"/>
            </geometry>
        </collision>
    </link>

    <link name="link1">
        <inertial>
            <origin xyz="0.005056 -0.0078534 0.020887" rpy="0 0 0"/>
            <mass value="0.09728"/>
            <inertia ixx="0.00011" ixy="-0.00001" ixz="0.00001" iyy="0.00005" iyz="-0.00001" izz="0.00010"/>
        </inertial>
        <visual>
            <origin xyz="0 0 0" rpy="0 0 0"/>
            <geometry>
                <box size="0.1 0.1 0.1"/>
            </geometry>
            <material name="link1_material">
                <color rgba="0.56471 0.56471 0.56471 1"/>
            </material>
        </visual>
        <collision>
            <origin xyz="0 0 0" rpy="0 0 0"/>
            <geometry>
                <box size="0.1 0.1 0.1"/>
            </geometry>
        </collision>
    </link>

    <joint name="joint1" type="revolute">
        <origin xyz="0 0 0.0565" rpy="0 0 0"/>
        <parent link="base_link"/>
        <child link="link1"/>
        <axis xyz="0 0 1"/>
        <limit lower="-10" upper="10" effort="100" velocity="1000"/>
    </joint>
    

<!-- 重复这个过程，为每个关节添加相应的 transmission 标签 -->
</robot>